2019-08-09 23:54:05,502 [ERROR]  Exception occurred while handling uri: 'http://localhost:5005/'
Traceback (most recent call last):
  File "C:\Users\ravindra\AppData\Roaming\Python\Python37\site-packages\sanic\app.py", line 893, in handle_request
    handler, args, kwargs, uri = self.router.get(request)
  File "C:\Users\ravindra\AppData\Roaming\Python\Python37\site-packages\sanic\router.py", line 407, in get
    return self._get(request.path, request.method, "")
  File "C:\Users\ravindra\AppData\Roaming\Python\Python37\site-packages\sanic\router.py", line 469, in _get
    raise NotFound("Requested URL {} not found".format(url))
sanic.exceptions.NotFound: Requested URL / not found
2019-08-09 23:54:05,699 [ERROR]  Exception occurred while handling uri: 'http://localhost:5005/favicon.ico'
Traceback (most recent call last):
  File "C:\Users\ravindra\AppData\Roaming\Python\Python37\site-packages\sanic\app.py", line 893, in handle_request
    handler, args, kwargs, uri = self.router.get(request)
  File "C:\Users\ravindra\AppData\Roaming\Python\Python37\site-packages\sanic\router.py", line 407, in get
    return self._get(request.path, request.method, "")
  File "C:\Users\ravindra\AppData\Roaming\Python\Python37\site-packages\sanic\router.py", line 469, in _get
    raise NotFound("Requested URL {} not found".format(url))
sanic.exceptions.NotFound: Requested URL /favicon.ico not found
2019-08-10 02:53:31,777 [ERROR]  Unable to start server
Traceback (most recent call last):
  File "C:\Users\ravindra\AppData\Roaming\Python\Python37\site-packages\sanic\server.py", line 745, in serve
    http_server = loop.run_until_complete(server_coroutine)
  File "c:\programdata\anaconda3\lib\asyncio\base_events.py", line 582, in run_until_complete
    raise RuntimeError('Event loop stopped before Future completed.')
RuntimeError: Event loop stopped before Future completed.
2019-08-10 03:00:40,830 [ERROR]  Unable to start server
Traceback (most recent call last):
  File "C:\Users\ravindra\AppData\Roaming\Python\Python37\site-packages\sanic\server.py", line 745, in serve
    http_server = loop.run_until_complete(server_coroutine)
  File "c:\programdata\anaconda3\lib\asyncio\base_events.py", line 582, in run_until_complete
    raise RuntimeError('Event loop stopped before Future completed.')
RuntimeError: Event loop stopped before Future completed.
2019-08-10 03:08:35,028 [ERROR]  Unable to start server
Traceback (most recent call last):
  File "C:\Users\ravindra\AppData\Roaming\Python\Python37\site-packages\sanic\server.py", line 745, in serve
    http_server = loop.run_until_complete(server_coroutine)
  File "c:\programdata\anaconda3\lib\asyncio\base_events.py", line 582, in run_until_complete
    raise RuntimeError('Event loop stopped before Future completed.')
RuntimeError: Event loop stopped before Future completed.
2019-08-11 00:41:01,044 [ERROR]  Exception occurred while handling uri: 'http://fa2d6261.ngrok.io/favicon.ico'
Traceback (most recent call last):
  File "C:\Users\ravindra\AppData\Roaming\Python\Python37\site-packages\sanic\app.py", line 893, in handle_request
    handler, args, kwargs, uri = self.router.get(request)
  File "C:\Users\ravindra\AppData\Roaming\Python\Python37\site-packages\sanic\router.py", line 407, in get
    return self._get(request.path, request.method, "")
  File "C:\Users\ravindra\AppData\Roaming\Python\Python37\site-packages\sanic\router.py", line 469, in _get
    raise NotFound("Requested URL {} not found".format(url))
sanic.exceptions.NotFound: Requested URL /favicon.ico not found
2019-08-11 01:24:35,677 [ERROR]  Exception occurred while handling uri: 'http://fa2d6261.ngrok.io//webhooks/rest/webhook'
Traceback (most recent call last):
  File "C:\Users\ravindra\AppData\Roaming\Python\Python37\site-packages\sanic\app.py", line 893, in handle_request
    handler, args, kwargs, uri = self.router.get(request)
  File "C:\Users\ravindra\AppData\Roaming\Python\Python37\site-packages\sanic\router.py", line 407, in get
    return self._get(request.path, request.method, "")
  File "C:\Users\ravindra\AppData\Roaming\Python\Python37\site-packages\sanic\router.py", line 469, in _get
    raise NotFound("Requested URL {} not found".format(url))
sanic.exceptions.NotFound: Requested URL //webhooks/rest/webhook not found
2019-08-11 14:06:17,761 [ERROR]  Exception occurred while handling uri: 'http://localhost:5005/'
Traceback (most recent call last):
  File "C:\Users\ravindra\AppData\Roaming\Python\Python37\site-packages\sanic\app.py", line 893, in handle_request
    handler, args, kwargs, uri = self.router.get(request)
  File "C:\Users\ravindra\AppData\Roaming\Python\Python37\site-packages\sanic\router.py", line 407, in get
    return self._get(request.path, request.method, "")
  File "C:\Users\ravindra\AppData\Roaming\Python\Python37\site-packages\sanic\router.py", line 446, in _get
    raise method_not_supported
sanic.exceptions.MethodNotSupported: Method POST not allowed for URL /
2019-08-11 14:06:23,782 [ERROR]  Exception occurred while handling uri: 'http://localhost:5005/'
Traceback (most recent call last):
  File "C:\Users\ravindra\AppData\Roaming\Python\Python37\site-packages\sanic\app.py", line 893, in handle_request
    handler, args, kwargs, uri = self.router.get(request)
  File "C:\Users\ravindra\AppData\Roaming\Python\Python37\site-packages\sanic\router.py", line 407, in get
    return self._get(request.path, request.method, "")
  File "C:\Users\ravindra\AppData\Roaming\Python\Python37\site-packages\sanic\router.py", line 446, in _get
    raise method_not_supported
sanic.exceptions.MethodNotSupported: Method POST not allowed for URL /
2019-08-11 14:58:01,398 [ERROR]  Exception occurred while handling uri: 'http://122518a6.ngrok.io/favicon.ico'
Traceback (most recent call last):
  File "C:\Users\ravindra\AppData\Roaming\Python\Python37\site-packages\sanic\app.py", line 893, in handle_request
    handler, args, kwargs, uri = self.router.get(request)
  File "C:\Users\ravindra\AppData\Roaming\Python\Python37\site-packages\sanic\router.py", line 407, in get
    return self._get(request.path, request.method, "")
  File "C:\Users\ravindra\AppData\Roaming\Python\Python37\site-packages\sanic\router.py", line 469, in _get
    raise NotFound("Requested URL {} not found".format(url))
sanic.exceptions.NotFound: Requested URL /favicon.ico not found
2019-08-11 14:58:49,358 [ERROR]  Exception occurred while handling uri: 'http://122518a6.ngrok.io/q=hi'
Traceback (most recent call last):
  File "C:\Users\ravindra\AppData\Roaming\Python\Python37\site-packages\sanic\app.py", line 893, in handle_request
    handler, args, kwargs, uri = self.router.get(request)
  File "C:\Users\ravindra\AppData\Roaming\Python\Python37\site-packages\sanic\router.py", line 407, in get
    return self._get(request.path, request.method, "")
  File "C:\Users\ravindra\AppData\Roaming\Python\Python37\site-packages\sanic\router.py", line 469, in _get
    raise NotFound("Requested URL {} not found".format(url))
sanic.exceptions.NotFound: Requested URL /q=hi not found
2019-08-11 14:58:49,836 [ERROR]  Exception occurred while handling uri: 'http://122518a6.ngrok.io/favicon.ico'
Traceback (most recent call last):
  File "C:\Users\ravindra\AppData\Roaming\Python\Python37\site-packages\sanic\app.py", line 893, in handle_request
    handler, args, kwargs, uri = self.router.get(request)
  File "C:\Users\ravindra\AppData\Roaming\Python\Python37\site-packages\sanic\router.py", line 407, in get
    return self._get(request.path, request.method, "")
  File "C:\Users\ravindra\AppData\Roaming\Python\Python37\site-packages\sanic\router.py", line 469, in _get
    raise NotFound("Requested URL {} not found".format(url))
sanic.exceptions.NotFound: Requested URL /favicon.ico not found
2019-08-11 14:58:56,166 [ERROR]  Exception occurred while handling uri: 'http://122518a6.ngrok.io/favicon.ico'
Traceback (most recent call last):
  File "C:\Users\ravindra\AppData\Roaming\Python\Python37\site-packages\sanic\app.py", line 893, in handle_request
    handler, args, kwargs, uri = self.router.get(request)
  File "C:\Users\ravindra\AppData\Roaming\Python\Python37\site-packages\sanic\router.py", line 407, in get
    return self._get(request.path, request.method, "")
  File "C:\Users\ravindra\AppData\Roaming\Python\Python37\site-packages\sanic\router.py", line 469, in _get
    raise NotFound("Requested URL {} not found".format(url))
sanic.exceptions.NotFound: Requested URL /favicon.ico not found
2019-08-11 15:23:56,576 [ERROR]  Exception occurred while handling uri: 'http://localhost:5005/'
Traceback (most recent call last):
  File "C:\Users\ravindra\AppData\Roaming\Python\Python37\site-packages\sanic\app.py", line 893, in handle_request
    handler, args, kwargs, uri = self.router.get(request)
  File "C:\Users\ravindra\AppData\Roaming\Python\Python37\site-packages\sanic\router.py", line 407, in get
    return self._get(request.path, request.method, "")
  File "C:\Users\ravindra\AppData\Roaming\Python\Python37\site-packages\sanic\router.py", line 446, in _get
    raise method_not_supported
sanic.exceptions.MethodNotSupported: Method POST not allowed for URL /
2019-08-11 15:25:40,101 [ERROR]  Exception occurred while handling uri: 'http://localhost:5005/favicon.ico'
Traceback (most recent call last):
  File "C:\Users\ravindra\AppData\Roaming\Python\Python37\site-packages\sanic\app.py", line 893, in handle_request
    handler, args, kwargs, uri = self.router.get(request)
  File "C:\Users\ravindra\AppData\Roaming\Python\Python37\site-packages\sanic\router.py", line 407, in get
    return self._get(request.path, request.method, "")
  File "C:\Users\ravindra\AppData\Roaming\Python\Python37\site-packages\sanic\router.py", line 469, in _get
    raise NotFound("Requested URL {} not found".format(url))
sanic.exceptions.NotFound: Requested URL /favicon.ico not found
2019-08-11 15:38:17,455 [ERROR]  Exception occurred while handling uri: 'http://localhost:5005/'
Traceback (most recent call last):
  File "C:\Users\ravindra\AppData\Roaming\Python\Python37\site-packages\sanic\app.py", line 893, in handle_request
    handler, args, kwargs, uri = self.router.get(request)
  File "C:\Users\ravindra\AppData\Roaming\Python\Python37\site-packages\sanic\router.py", line 407, in get
    return self._get(request.path, request.method, "")
  File "C:\Users\ravindra\AppData\Roaming\Python\Python37\site-packages\sanic\router.py", line 446, in _get
    raise method_not_supported
sanic.exceptions.MethodNotSupported: Method POST not allowed for URL /
2019-08-11 15:46:55,439 [ERROR]  Exception occurred while handling uri: 'http://7a86cdcd.ngrok.io/favicon.ico'
Traceback (most recent call last):
  File "C:\Users\ravindra\AppData\Roaming\Python\Python37\site-packages\sanic\app.py", line 893, in handle_request
    handler, args, kwargs, uri = self.router.get(request)
  File "C:\Users\ravindra\AppData\Roaming\Python\Python37\site-packages\sanic\router.py", line 407, in get
    return self._get(request.path, request.method, "")
  File "C:\Users\ravindra\AppData\Roaming\Python\Python37\site-packages\sanic\router.py", line 469, in _get
    raise NotFound("Requested URL {} not found".format(url))
sanic.exceptions.NotFound: Requested URL /favicon.ico not found
2019-08-11 16:05:26,137 [ERROR]  Exception occurred while handling uri: 'http://localhost:5005/'
Traceback (most recent call last):
  File "C:\Users\ravindra\AppData\Roaming\Python\Python37\site-packages\sanic\app.py", line 893, in handle_request
    handler, args, kwargs, uri = self.router.get(request)
  File "C:\Users\ravindra\AppData\Roaming\Python\Python37\site-packages\sanic\router.py", line 407, in get
    return self._get(request.path, request.method, "")
  File "C:\Users\ravindra\AppData\Roaming\Python\Python37\site-packages\sanic\router.py", line 446, in _get
    raise method_not_supported
sanic.exceptions.MethodNotSupported: Method POST not allowed for URL /
2019-08-11 16:09:50,771 [ERROR]  Exception occurred while handling uri: 'http://localhost:5005/'
Traceback (most recent call last):
  File "C:\Users\ravindra\AppData\Roaming\Python\Python37\site-packages\sanic\app.py", line 893, in handle_request
    handler, args, kwargs, uri = self.router.get(request)
  File "C:\Users\ravindra\AppData\Roaming\Python\Python37\site-packages\sanic\router.py", line 407, in get
    return self._get(request.path, request.method, "")
  File "C:\Users\ravindra\AppData\Roaming\Python\Python37\site-packages\sanic\router.py", line 446, in _get
    raise method_not_supported
sanic.exceptions.MethodNotSupported: Method POST not allowed for URL /
